<?xml version="1.0"?>
<robot name="swedish_wheel" xmlns:xacro="http://ros.org/wiki/xacro">
    
  <xacro:macro name="sw_wheel" params="wheel_prefix *joint_pose">

		<link name="${wheel_prefix}_wheel_link">
			<visual>
        <origin xyz="0 0 0" rpy="0 0 0"/>
        <geometry>
            <mesh filename="package://robots_rycsv_description/meshes/sw_wheel.dae" scale="0.01 0.01 0.01"/>
        </geometry>
    </visual>
    <collision>
        <origin xyz="0 0 0" rpy="${pi/2} 0 0"/>
        <geometry>
            <sphere radius="0.06"/>
        </geometry>
    </collision>
    <inertial>
        <origin rpy="0 0 0" xyz="0.000091 -0.000123 -0.000182"/>
        <mass value="0.315" />
        <inertia    ixx="0.000353139" 
                    iyy="0.000706278" 
                    izz="0.000353139" 
                    ixy="0.0" 
                    ixz="0.0" 
                    iyz="0.0" />
    </inertial>
		</link>

		<gazebo reference="${wheel_prefix}_wheel_link">
			<mu1>0.01</mu1>
      <mu2>1</mu2>
      <fdir1>0 0 1</fdir1>
		</gazebo>

		<joint name="${wheel_prefix}_wheel" type="continuous">
			<parent link="base_link"/>
			<child link="${wheel_prefix}_wheel_link"/>
			<xacro:insert_block name="joint_pose"/>
			<axis xyz="0 1 0" rpy="0 0 0" />
		</joint>

		<transmission name="${wheel_prefix}_wheel_trans" type="SimpleTransmission">
			<type>transmission_interface/SimpleTransmission</type>
			<actuator name="${wheel_prefix}_wheel_motor">
				<mechanicalReduction>1</mechanicalReduction>
			</actuator>
			<joint name="${wheel_prefix}_wheel">
				<hardwareInterface>hardware_interface/VelocityJointInterface</hardwareInterface>
			</joint>
		</transmission>

	</xacro:macro>

</robot>